2024-08-08 12:04:05,422 INFO    StreamThr :208010 [internal.py:wandb_internal():86] W&B internal server running at pid: 208010, started at: 2024-08-08 12:04:05.421951
2024-08-08 12:04:05,423 DEBUG   HandlerThread:208010 [handler.py:handle_request():146] handle_request: status
2024-08-08 12:04:05,424 INFO    WriterThread:208010 [datastore.py:open_for_write():85] open: /home/rwkv/JL/GMM/llama/wandb/run-20240808_120405-tkif170s/run-tkif170s.wandb
2024-08-08 12:04:05,424 DEBUG   SenderThread:208010 [sender.py:send():382] send: header
2024-08-08 12:04:05,454 DEBUG   SenderThread:208010 [sender.py:send():382] send: run
2024-08-08 12:04:10,455 DEBUG   HandlerThread:208010 [handler.py:handle_request():146] handle_request: keepalive
2024-08-08 12:04:15,457 DEBUG   HandlerThread:208010 [handler.py:handle_request():146] handle_request: keepalive
2024-08-08 12:04:20,458 DEBUG   HandlerThread:208010 [handler.py:handle_request():146] handle_request: keepalive
2024-08-08 12:04:25,460 DEBUG   HandlerThread:208010 [handler.py:handle_request():146] handle_request: keepalive
2024-08-08 12:04:30,462 DEBUG   HandlerThread:208010 [handler.py:handle_request():146] handle_request: keepalive
2024-08-08 12:04:35,463 DEBUG   HandlerThread:208010 [handler.py:handle_request():146] handle_request: keepalive
2024-08-08 12:04:40,465 DEBUG   HandlerThread:208010 [handler.py:handle_request():146] handle_request: keepalive
2024-08-08 12:04:45,466 DEBUG   HandlerThread:208010 [handler.py:handle_request():146] handle_request: keepalive
2024-08-08 12:04:50,468 DEBUG   HandlerThread:208010 [handler.py:handle_request():146] handle_request: keepalive
2024-08-08 12:04:55,469 DEBUG   HandlerThread:208010 [handler.py:handle_request():146] handle_request: keepalive
2024-08-08 12:05:00,471 DEBUG   HandlerThread:208010 [handler.py:handle_request():146] handle_request: keepalive
2024-08-08 12:05:05,473 DEBUG   HandlerThread:208010 [handler.py:handle_request():146] handle_request: keepalive
2024-08-08 12:05:08,847 INFO    SenderThread:208010 [retry.py:__call__():172] Retry attempt failed:
Traceback (most recent call last):
  File "/home/rwkv/miniconda3/lib/python3.10/site-packages/urllib3/connection.py", line 203, in _new_conn
    sock = connection.create_connection(
  File "/home/rwkv/miniconda3/lib/python3.10/site-packages/urllib3/util/connection.py", line 85, in create_connection
    raise err
  File "/home/rwkv/miniconda3/lib/python3.10/site-packages/urllib3/util/connection.py", line 73, in create_connection
    sock.connect(sa)
TimeoutError: timed out

The above exception was the direct cause of the following exception:

Traceback (most recent call last):
  File "/home/rwkv/miniconda3/lib/python3.10/site-packages/urllib3/connectionpool.py", line 790, in urlopen
    response = self._make_request(
  File "/home/rwkv/miniconda3/lib/python3.10/site-packages/urllib3/connectionpool.py", line 496, in _make_request
    conn.request(
  File "/home/rwkv/miniconda3/lib/python3.10/site-packages/urllib3/connection.py", line 395, in request
    self.endheaders()
  File "/home/rwkv/miniconda3/lib/python3.10/http/client.py", line 1278, in endheaders
    self._send_output(message_body, encode_chunked=encode_chunked)
  File "/home/rwkv/miniconda3/lib/python3.10/http/client.py", line 1038, in _send_output
    self.send(msg)
  File "/home/rwkv/miniconda3/lib/python3.10/http/client.py", line 976, in send
    self.connect()
  File "/home/rwkv/miniconda3/lib/python3.10/site-packages/urllib3/connection.py", line 243, in connect
    self.sock = self._new_conn()
  File "/home/rwkv/miniconda3/lib/python3.10/site-packages/urllib3/connection.py", line 212, in _new_conn
    raise ConnectTimeoutError(
urllib3.exceptions.ConnectTimeoutError: (<urllib3.connection.HTTPConnection object at 0x74c07d489fc0>, 'Connection to dian.sea-group.org timed out. (connect timeout=20)')

The above exception was the direct cause of the following exception:

Traceback (most recent call last):
  File "/home/rwkv/miniconda3/lib/python3.10/site-packages/requests/adapters.py", line 486, in send
    resp = conn.urlopen(
  File "/home/rwkv/miniconda3/lib/python3.10/site-packages/urllib3/connectionpool.py", line 844, in urlopen
    retries = retries.increment(
  File "/home/rwkv/miniconda3/lib/python3.10/site-packages/urllib3/util/retry.py", line 515, in increment
    raise MaxRetryError(_pool, url, reason) from reason  # type: ignore[arg-type]
urllib3.exceptions.MaxRetryError: HTTPConnectionPool(host='dian.sea-group.org', port=9098): Max retries exceeded with url: /graphql (Caused by ConnectTimeoutError(<urllib3.connection.HTTPConnection object at 0x74c07d489fc0>, 'Connection to dian.sea-group.org timed out. (connect timeout=20)'))

During handling of the above exception, another exception occurred:

Traceback (most recent call last):
  File "/home/rwkv/miniconda3/lib/python3.10/site-packages/wandb/sdk/lib/retry.py", line 131, in __call__
    result = self._call_fn(*args, **kwargs)
  File "/home/rwkv/miniconda3/lib/python3.10/site-packages/wandb/sdk/internal/internal_api.py", line 369, in execute
    return self.client.execute(*args, **kwargs)  # type: ignore
  File "/home/rwkv/miniconda3/lib/python3.10/site-packages/wandb/vendor/gql-0.2.0/wandb_gql/client.py", line 52, in execute
    result = self._get_result(document, *args, **kwargs)
  File "/home/rwkv/miniconda3/lib/python3.10/site-packages/wandb/vendor/gql-0.2.0/wandb_gql/client.py", line 60, in _get_result
    return self.transport.execute(document, *args, **kwargs)
  File "/home/rwkv/miniconda3/lib/python3.10/site-packages/wandb/sdk/lib/gql_request.py", line 58, in execute
    request = self.session.post(self.url, **post_args)
  File "/home/rwkv/miniconda3/lib/python3.10/site-packages/requests/sessions.py", line 637, in post
    return self.request("POST", url, data=data, json=json, **kwargs)
  File "/home/rwkv/miniconda3/lib/python3.10/site-packages/requests/sessions.py", line 589, in request
    resp = self.send(prep, **send_kwargs)
  File "/home/rwkv/miniconda3/lib/python3.10/site-packages/requests/sessions.py", line 703, in send
    r = adapter.send(request, **kwargs)
  File "/home/rwkv/miniconda3/lib/python3.10/site-packages/requests/adapters.py", line 507, in send
    raise ConnectTimeout(e, request=request)
requests.exceptions.ConnectTimeout: HTTPConnectionPool(host='dian.sea-group.org', port=9098): Max retries exceeded with url: /graphql (Caused by ConnectTimeoutError(<urllib3.connection.HTTPConnection object at 0x74c07d489fc0>, 'Connection to dian.sea-group.org timed out. (connect timeout=20)'))
2024-08-08 12:05:10,473 DEBUG   HandlerThread:208010 [handler.py:handle_request():146] handle_request: keepalive
2024-08-08 12:05:15,475 DEBUG   HandlerThread:208010 [handler.py:handle_request():146] handle_request: keepalive
2024-08-08 12:05:20,477 DEBUG   HandlerThread:208010 [handler.py:handle_request():146] handle_request: keepalive
2024-08-08 12:05:25,478 DEBUG   HandlerThread:208010 [handler.py:handle_request():146] handle_request: keepalive
2024-08-08 12:05:30,480 DEBUG   HandlerThread:208010 [handler.py:handle_request():146] handle_request: keepalive
2024-08-08 12:05:35,482 DEBUG   HandlerThread:208010 [handler.py:handle_request():146] handle_request: cancel
2024-08-08 12:05:35,482 DEBUG   SenderThread:208010 [sender.py:send():391] Record cancelled: run
2024-08-08 12:05:35,483 DEBUG   HandlerThread:208010 [handler.py:handle_request():146] handle_request: status_report
2024-08-08 12:05:35,483 DEBUG   HandlerThread:208010 [handler.py:handle_request():146] handle_request: cancel
2024-08-08 12:05:35,692 DEBUG   HandlerThread:208010 [handler.py:handle_request():146] handle_request: shutdown
2024-08-08 12:05:35,692 INFO    HandlerThread:208010 [handler.py:finish():866] shutting down handler
2024-08-08 12:05:36,483 INFO    SenderThread:208010 [sender.py:finish():1548] shutting down sender
2024-08-08 12:05:36,484 INFO    WriterThread:208010 [datastore.py:close():294] close: /home/rwkv/JL/GMM/llama/wandb/run-20240808_120405-tkif170s/run-tkif170s.wandb
